<?xml version='1.0'?>

<robot name="rover" xmlns:xacro="http://www.ros.org/wiki/xacro">

  <link name='base_footprint'>
    <pose>0 0 0 0 0 0</pose>

    <inertial>
      <mass value="15.0"/>
      <origin xyz="0.0 0 0.1" rpy=" 0 0 0"/>
      <inertia
          ixx="0.1" 
          ixy="0" 
          ixz="0"
          iyy="0.1" 
          iyz="0"
          izz="0.1"/>
    </inertial>

    <collision name='collision'>
      <origin xyz="0 0 0.15" rpy=" 0 0 0"/>
      <geometry>
        <box size= "0.5 0.5 0.35"/>
      </geometry>
    </collision>

    <visual name='base_footprint_visual'>
      <origin xyz="0 0 0.15" rpy=" 0 0 0"/>
      <geometry>
      
        <box size= "0.5 0.5 0.35"/>
      </geometry>
    </visual>
  </link>

  <link name="left_wheel_front">
    <collision name="collision">
      <origin xyz="0 0 0" rpy="0 1.5707 1.5707"/>
      <geometry>
        <cylinder radius="0.13" length="0.04"/>
      </geometry>
    </collision>

    <visual name="left_wheel_visual">
      <origin xyz="0 0 0" rpy="0 1.5707 1.5707"/>
      <geometry>
        <cylinder radius="0.13" length="0.04"/>
      </geometry>
    </visual>

    <inertial>
      <origin xyz="0 0 0" rpy="0 1.5707 1.5707"/>
      <mass value="5"/>
      <inertia
        ixx=".1" ixy="0.0" ixz="0.0"
        iyy=".1" iyz="0.0"
        izz=".1"/>
    </inertial>
  </link>

  <link name="right_wheel_front">
    <collision name="collision">
      <origin xyz="0 0 0" rpy="0 1.5707 1.5707"/>
      <geometry>
        <cylinder radius="0.13" length="0.04"/>
      </geometry>
    </collision>

    <visual name="right_wheel_visual">
      <origin xyz="0 0 0" rpy="0 1.5707 1.5707"/>
      <geometry>
        <cylinder radius="0.13" length="0.04"/>
      </geometry>
    </visual>

    <inertial>
      <origin xyz="0 0 0" rpy="0 1.5707 1.5707"/>
      <mass value="5"/>
      <inertia
        ixx=".1" ixy="0.0" ixz="0.0"
        iyy=".1" iyz="0.0"
        izz=".1"/>
    </inertial>
  </link>

  <link name="base_sonar_front">
    <collision>
      <origin xyz="0 0 0" rpy="0 0 0"/>
      <geometry>
        <box size="0.01 0.01 0.01"/>
      </geometry>
    </collision>
    <visual>
      <origin xyz="0 0 0" rpy="0 0 0"/>
      <geometry>
        <box size="0.01 0.01 0.01"/>
      </geometry>
    </visual>
    <inertial>
      <mass value="1e-5" />
      <origin xyz="0 0 0" rpy="0 0 0"/>
      <inertia ixx="1e-6" ixy="0" ixz="0" iyy="1e-6" iyz="0" izz="1e-6" />
    </inertial>
 </link>

  
  <joint type="continuous" name="left_wheel_front_hinge">
    <origin xyz="0.0 0.29 0.1" rpy="0 0 0"/>
    <child link="left_wheel_front"/>
    <parent link="base_footprint"/>
    <axis xyz="0 1 0" rpy="0 0 0"/>
    <limit effort="10000" velocity="1000"/>
    <joint_properties damping="1.0" friction="1.0"/>
  </joint>

  <joint type="continuous" name="right_wheel_front_hinge">
    <origin xyz="0.0 -0.29 0.1" rpy="0 0 0"/>
    <child link="right_wheel_front"/>
    <parent link="base_footprint"/>
    <axis xyz="0 1 0" rpy="0 0 0"/>
    <limit effort="10000" velocity="1000"/>
    <joint_properties damping="1.0" friction="1.0"/>
  </joint>

  <joint name="sonar_front_joint" type="fixed">
    <axis xyz="0 1 0" />
    <origin rpy="0 0 0" xyz="0.25 0 0.25" />
    <parent link="base_footprint"/>
    <child link="base_sonar_front"/>
  </joint>  

</robot>
